<?xml version="1.0" ?>
<robot name="converted_robot">
   <link name="world">
      <inertial>
         <origin xyz="0.0 0.0 0.0" rpy="0.0 0.0 0.0"/>
         <mass value="0.0"/>
         <inertia ixx="0.0" iyy="0.0" izz="0.0" ixy="0" ixz="0" iyz="0"/>
      </inertial>
   </link>
   <link name="root">
      <inertial>
         <origin xyz="0.0 0.0 0.0" rpy="0.0 0.0 0.0"/>
         <mass value="0.0"/>
         <inertia ixx="0.0" iyy="0.0" izz="0.0" ixy="0" ixz="0" iyz="0"/>
      </inertial>
   </link>
   <link name="world2root_fixed_jointbody">
      <inertial>
         <origin xyz="0.0 0.0 0.0" rpy="0.0 0.0 0.0"/>
         <mass value="0.001"/>
         <inertia ixx="1e-09" iyy="1e-09" izz="1e-09" ixy="0" ixz="0" iyz="0"/>
      </inertial>
   </link>
   <joint type="fixed" name="world2root_fixed">
      <parent link="world"/>
      <child link="world2root_fixed_jointbody"/>
      <origin xyz="0.0 0.0 0.0" rpy="0.0 0.0 0.0"/>
   </joint>
   <joint type="fixed" name="world2root_fixed_offset">
      <parent link="world2root_fixed_jointbody"/>
      <child link="root"/>
      <origin xyz="-0.0 -0.0 -0.0" rpy="0.0 0.0 0.0"/>
   </joint>
   <link name="tower">
      <inertial>
         <origin xyz="-0.012935936040143856 -0.1250798428773428 -0.0001711974765966958" rpy="1.5378790315260968 -1.5027760115029016 -2.9935622097884105"/>
         <mass value="0.791434072813212"/>
         <inertia ixx="0.0014927212233772481" iyy="0.0014084035095714637" izz="0.0005242023751306965" ixy="0" ixz="0" iyz="0"/>
      </inertial>
      <visual name="tower">
         <origin xyz="-0.012935936040143856 -0.1250798428773428 -0.0001711974765966958" rpy="1.5378790315260975 -1.5027760115029016 -2.9935622097884114"/>
         <geometry>
            <mesh filename="package://viz/models/URDF_Simulation/converted_tower.stl"/>
         </geometry>
         <material name="white"/>
      </visual>
   </link>
   <link name="root2tower_fixed_jointbody">
      <inertial>
         <origin xyz="0.0 0.0 0.0" rpy="0.0 0.0 0.0"/>
         <mass value="0.001"/>
         <inertia ixx="1e-09" iyy="1e-09" izz="1e-09" ixy="0" ixz="0" iyz="0"/>
      </inertial>
   </link>
   <joint type="fixed" name="root2tower_fixed">
      <parent link="root"/>
      <child link="root2tower_fixed_jointbody"/>
      <origin xyz="-0.0132 0.0 0.017" rpy="1.5715926535897906 2.113124342173478e-09 3.1415900000008414"/>
   </joint>
   <joint type="fixed" name="root2tower_fixed_offset">
      <parent link="root2tower_fixed_jointbody"/>
      <child link="tower"/>
      <origin xyz="-0.0 -0.0 -0.0" rpy="0.0 0.0 0.0"/>
   </joint>
   <link name="wrist_1">
      <inertial>
         <origin xyz="-0.014332709818484647 -0.06084959605214876 0.00010921642133937277" rpy="1.5708004130834685 1.528474215972686e-05 1.5650097032208263"/>
         <mass value="0.058899626515319804"/>
         <inertia ixx="3.753569655681751e-05" iyy="3.3836482834552355e-05" izz="9.284974380360733e-06" ixy="0" ixz="0" iyz="0"/>
      </inertial>
      <visual name="wrist_3">
         <origin xyz="-0.014332709818484647 -0.06084959605214876 0.00010921642133937277" rpy="1.5708004130834687 1.5284742159948905e-05 1.5650097032208266"/>
         <geometry>
            <mesh filename="package://viz/models/URDF_Simulation/converted_wrist_3.stl"/>
         </geometry>
         <material name="white"/>
      </visual>
   </link>
   <link name="tower2wrist_1_fixed_jointbody">
      <inertial>
         <origin xyz="0.0 0.0 0.0" rpy="0.0 0.0 0.0"/>
         <mass value="0.001"/>
         <inertia ixx="1e-09" iyy="1e-09" izz="1e-09" ixy="0" ixz="0" iyz="0"/>
      </inertial>
   </link>
   <joint type="fixed" name="tower2wrist_1_fixed">
      <parent link="tower"/>
      <child link="tower2wrist_1_fixed_jointbody"/>
      <origin xyz="0.0 0.0 0.0" rpy="0.0 0.0 0.0"/>
   </joint>
   <joint type="fixed" name="tower2wrist_1_fixed_offset">
      <parent link="tower2wrist_1_fixed_jointbody"/>
      <child link="wrist_1"/>
      <origin xyz="-0.0 -0.0 -0.0" rpy="0.0 0.0 0.0"/>
   </joint>
   <link name="wrist_2">
      <inertial>
         <origin xyz="-0.011749586365455653 -0.03917818231353612 0.00011052945291615456" rpy="-1.8092865401767204 -1.5661853121132732 -1.2638218544209279"/>
         <mass value="0.020757970653264464"/>
         <inertia ixx="2.3183204340638643e-05" iyy="2.2130131511678158e-05" izz="1.4714793045715701e-06" ixy="0" ixz="0" iyz="0"/>
      </inertial>
      <visual name="wrist_1">
         <origin xyz="-0.04685505325225877 -0.034649420343556225 0.0002783448473589519" rpy="1.5707963267948966 0.0 2.987432783863472"/>
         <geometry>
            <mesh filename="package://viz/models/URDF_Simulation/converted_wrist_1.stl"/>
         </geometry>
         <material name="white"/>
      </visual>
      <visual name="wrist_2">
         <origin xyz="-0.004873884468205962 -0.04006517855744275 7.766139194779857e-05" rpy="1.3548527125878218 -1.5707870578414207 1.9119197405906991"/>
         <geometry>
            <mesh filename="package://viz/models/URDF_Simulation/converted_wrist_2.stl"/>
         </geometry>
         <material name="white"/>
      </visual>
   </link>
   <link name="wrist_jointbody">
      <inertial>
         <origin xyz="0.0 0.0 0.0" rpy="0.0 0.0 0.0"/>
         <mass value="0.001"/>
         <inertia ixx="1e-09" iyy="1e-09" izz="1e-09" ixy="0" ixz="0" iyz="0"/>
      </inertial>
   </link>
   <joint type="revolute" name="wrist">
      <parent link="wrist_1"/>
      <child link="wrist_jointbody"/>
      <origin xyz="0.0 -0.0463 0.0" rpy="0.0 0.0 0.0"/>
      <axis xyz="1.0 0.0 0.0"/>
      <limit lower="-2.27" upper="2.27" effort="100" velocity="100"/>
   </joint>
   <joint type="fixed" name="wrist_offset">
      <parent link="wrist_jointbody"/>
      <child link="wrist_2"/>
      <origin xyz="-0.0 0.0463 -0.0" rpy="0.0 0.0 0.0"/>
   </joint>
   <link name="palm">
      <inertial>
         <origin xyz="-0.009750183589572366 0.04021403488529142 -0.00039237105510929893" rpy="2.3172560848423656 -1.562874237700241 2.192255222809746"/>
         <mass value="0.16567872925570942"/>
         <inertia ixx="0.0002358825828115673" iyy="0.00017096319828277548" izz="6.854952483029862e-05" ixy="0" ixz="0" iyz="0"/>
      </inertial>
      <visual name="palm_tower">
         <origin xyz="-0.009750183589572366 0.04021403488529142 -0.00039237105510929893" rpy="2.3172560848423656 -1.562874237700241 2.192255222809746"/>
         <geometry>
            <mesh filename="package://viz/models/URDF_Simulation/converted_palm_tower.stl"/>
         </geometry>
         <material name="white"/>
      </visual>
   </link>
   <link name="wrist_22palm_fixed_jointbody">
      <inertial>
         <origin xyz="0.0 0.0 0.0" rpy="0.0 0.0 0.0"/>
         <mass value="0.001"/>
         <inertia ixx="1e-09" iyy="1e-09" izz="1e-09" ixy="0" ixz="0" iyz="0"/>
      </inertial>
   </link>
   <joint type="fixed" name="wrist_22palm_fixed">
      <parent link="wrist_2"/>
      <child link="wrist_22palm_fixed_jointbody"/>
      <origin xyz="0.0 0.0 0.0" rpy="0.0 0.0 0.0"/>
   </joint>
   <joint type="fixed" name="wrist_22palm_fixed_offset">
      <parent link="wrist_22palm_fixed_jointbody"/>
      <child link="palm"/>
      <origin xyz="-0.0 -0.0 -0.0" rpy="0.0 0.0 0.0"/>
   </joint>
   <link name="thumb_base">
      <inertial>
         <origin xyz="-0.05388722858794558 -0.08972924545530461 0.0056400640968846715" rpy="1.1981321937913696 -1.4948979105066995 0.7661853183228415"/>
         <mass value="0.015400950262490496"/>
         <inertia ixx="4.057013831282678e-06" iyy="3.3189900464939896e-06" izz="1.0886313012479005e-06" ixy="0" ixz="0" iyz="0"/>
      </inertial>
      <visual name="thumb_base">
         <origin xyz="-0.05388722858794558 -0.08972924545530461 0.0056400640968846715" rpy="1.1981321937913676 -1.4948979105066995 0.7661853183228435"/>
         <geometry>
            <mesh filename="package://viz/models/URDF_Simulation/converted_thumb_base.stl"/>
         </geometry>
         <material name="white"/>
      </visual>
   </link>
   <link name="root2thumb_base_jointbody">
      <inertial>
         <origin xyz="0.0 0.0 0.0" rpy="0.0 0.0 0.0"/>
         <mass value="0.001"/>
         <inertia ixx="1e-09" iyy="1e-09" izz="1e-09" ixy="0" ixz="0" iyz="0"/>
      </inertial>
   </link>
   <joint type="revolute" name="root2thumb_base">
      <parent link="palm"/>
      <child link="root2thumb_base_jointbody"/>
      <origin xyz="0.01810025051214078 0.00810024353395844 0.002000000000000001" rpy="0.0 0.0 1.5707999999999998"/>
      <axis xyz="-0.872045190552692 0.48942536267945813 0.0"/>
      <limit lower="0.0" upper="2.27" effort="100" velocity="100"/>
   </joint>
   <joint type="fixed" name="root2thumb_base_offset">
      <parent link="root2thumb_base_jointbody"/>
      <child link="thumb_base"/>
      <origin xyz="0.0682 0.0663 -0.009" rpy="0.0 0.0 0.0"/>
   </joint>
   <link name="thumb_um_virt">
      <inertial>
         <origin xyz="0.0 0.0 0.0" rpy="0.0 0.0 0.0"/>
         <mass value="0.001"/>
         <inertia ixx="4e-10" iyy="4e-10" izz="3e-10" ixy="0" ixz="0" iyz="0"/>
      </inertial>
   </link>
   <link name="thumb_abd_virt_jointbody">
      <inertial>
         <origin xyz="0.0 0.0 0.0" rpy="0.0 0.0 0.0"/>
         <mass value="0.001"/>
         <inertia ixx="1e-09" iyy="1e-09" izz="1e-09" ixy="0" ixz="0" iyz="0"/>
      </inertial>
   </link>
   <joint type="revolute" name="thumb_abd_virt">
      <parent link="thumb_base"/>
      <child link="thumb_abd_virt_jointbody"/>
      <origin xyz="-0.05696 -0.11383 0.0" rpy="0.0 0.0 0.0"/>
      <axis xyz="0.0 0.0 1.0"/>
      <limit lower="-0.523599" upper="0.523599" effort="100" velocity="100"/>
   </joint>
   <joint type="fixed" name="thumb_abd_virt_offset">
      <parent link="thumb_abd_virt_jointbody"/>
      <child link="thumb_um_virt"/>
      <origin xyz="0.05696 0.11383 -0.0" rpy="0.0 0.0 0.0"/>
   </joint>
   <link name="thumb_um">
      <inertial>
         <origin xyz="-0.06002974424873159 -0.11906183356660797 0.0062186112018148216" rpy="-0.0012484400387758887 0.391076545340286 1.0465689521908192"/>
         <mass value="0.0020561829545655487"/>
         <inertia ixx="5.3193394084926844e-08" iyy="4.4699706473833634e-08" izz="4.1958930900945313e-08" ixy="0" ixz="0" iyz="0"/>
      </inertial>
      <visual name="thumb_um">
         <origin xyz="-0.06002974424873159 -0.11906183356660797 0.0062186112018148216" rpy="-0.0012484400387758887 0.391076545340286 1.0465689521908192"/>
         <geometry>
            <mesh filename="package://viz/models/URDF_Simulation/converted_thumb_um.stl"/>
         </geometry>
         <material name="white"/>
      </visual>
   </link>
   <link name="thumb_abd_jointbody">
      <inertial>
         <origin xyz="0.0 0.0 0.0" rpy="0.0 0.0 0.0"/>
         <mass value="0.001"/>
         <inertia ixx="1e-09" iyy="1e-09" izz="1e-09" ixy="0" ixz="0" iyz="0"/>
      </inertial>
   </link>
   <joint type="revolute" name="thumb_abd">
      <parent link="thumb_um_virt"/>
      <child link="thumb_abd_jointbody"/>
      <origin xyz="-0.05696 -0.11383 0.0" rpy="0.0 0.0 0.0"/>
      <axis xyz="0.0 0.0 1.0"/>
      <limit lower="-0.523599" upper="0.523599" effort="100" velocity="100"/>
   </joint>
   <joint type="fixed" name="thumb_abd_offset">
      <parent link="thumb_abd_jointbody"/>
      <child link="thumb_um"/>
      <origin xyz="0.05696 0.11383 -0.0" rpy="0.0 0.0 0.0"/>
   </joint>
   <link name="thumb_mp_virt">
      <inertial>
         <origin xyz="0.009525 -0.041187 0.083647" rpy="-0.22291598477092758 -1.2682876286119864 0.3020329839181935"/>
         <mass value="0.001"/>
         <inertia ixx="4e-10" iyy="4e-10" izz="3e-10" ixy="0" ixz="0" iyz="0"/>
      </inertial>
   </link>
   <link name="thumb_um2mp_virt_jointbody">
      <inertial>
         <origin xyz="0.0 0.0 0.0" rpy="0.0 0.0 0.0"/>
         <mass value="0.001"/>
         <inertia ixx="1e-09" iyy="1e-09" izz="1e-09" ixy="0" ixz="0" iyz="0"/>
      </inertial>
   </link>
   <joint type="revolute" name="thumb_um2mp_virt">
      <parent link="thumb_um"/>
      <child link="thumb_um2mp_virt_jointbody"/>
      <origin xyz="-0.072947 -0.114166 0.008" rpy="0.0 0.0 0.0"/>
      <axis xyz="-0.872045190552692 0.48942536267945813 0.0"/>
      <limit lower="-0.16" upper="1.308" effort="100" velocity="100"/>
   </joint>
   <joint type="fixed" name="thumb_um2mp_virt_offset">
      <parent link="thumb_um2mp_virt_jointbody"/>
      <child link="thumb_mp_virt"/>
      <origin xyz="0.072947 0.114166 -0.008" rpy="0.0 0.0 0.0"/>
   </joint>
   <link name="thumb_mp">
      <inertial>
         <origin xyz="-0.07215929044573305 -0.14052795432320075 0.00551798779969882" rpy="2.9311721332498637 -1.5138717843315774 -1.881310598490373"/>
         <mass value="0.007559331420198066"/>
         <inertia ixx="9.573996733464855e-07" iyy="9.284932904903027e-07" izz="1.7221260520814514e-07" ixy="0" ixz="0" iyz="0"/>
      </inertial>
      <visual name="thumb_mp">
         <origin xyz="-0.07215929044573305 -0.14052795432320075 0.00551798779969882" rpy="2.9311721332498664 -1.5138717843315772 -1.8813105984903749"/>
         <geometry>
            <mesh filename="package://viz/models/URDF_Simulation/converted_thumb_mp.stl"/>
         </geometry>
         <material name="white"/>
      </visual>
   </link>
   <link name="thumb_um2mp_jointbody">
      <inertial>
         <origin xyz="0.0 0.0 0.0" rpy="0.0 0.0 0.0"/>
         <mass value="0.001"/>
         <inertia ixx="1e-09" iyy="1e-09" izz="1e-09" ixy="0" ixz="0" iyz="0"/>
      </inertial>
   </link>
   <joint type="revolute" name="thumb_um2mp">
      <parent link="thumb_mp_virt"/>
      <child link="thumb_um2mp_jointbody"/>
      <origin xyz="-0.062947 -0.124166 0.008" rpy="0.0 0.0 0.0"/>
      <axis xyz="-0.872045190552692 0.48942536267945813 0.0"/>
      <limit lower="-0.16" upper="1.308" effort="100" velocity="100"/>
   </joint>
   <joint type="fixed" name="thumb_um2mp_offset">
      <parent link="thumb_um2mp_jointbody"/>
      <child link="thumb_mp"/>
      <origin xyz="0.062947 0.124166 -0.008" rpy="0.0 0.0 0.0"/>
   </joint>
   <link name="index_um_virt">
      <inertial>
         <origin xyz="0.0 0.0 0.0" rpy="0.0 0.0 0.0"/>
         <mass value="0.001"/>
         <inertia ixx="4e-10" iyy="4e-10" izz="3e-10" ixy="0" ixz="0" iyz="0"/>
      </inertial>
   </link>
   <link name="index_abd_virt_jointbody">
      <inertial>
         <origin xyz="0.0 0.0 0.0" rpy="0.0 0.0 0.0"/>
         <mass value="0.001"/>
         <inertia ixx="1e-09" iyy="1e-09" izz="1e-09" ixy="0" ixz="0" iyz="0"/>
      </inertial>
   </link>
   <joint type="revolute" name="index_abd_virt">
      <parent link="palm"/>
      <child link="index_abd_virt_jointbody"/>
      <origin xyz="0.0250405 0.0852 0.0" rpy="-1.5707963267948966 1.5707963267948966 0.0"/>
      <axis xyz="1.0 0.0 0.0"/>
      <limit lower="-0.264" upper="0.264" effort="100" velocity="100"/>
   </joint>
   <joint type="fixed" name="index_abd_virt_offset">
      <parent link="index_abd_virt_jointbody"/>
      <child link="index_um_virt"/>
      <origin xyz="-0.0 -0.0 -0.0" rpy="0.0 0.0 0.0"/>
   </joint>
   <link name="index_um">
      <inertial>
         <origin xyz="0.0003158098365906876 -0.00022882513673609314 -0.0036213650800712305" rpy="3.11344183213456 -1.2906456267839208 -3.102620114783569"/>
         <mass value="0.0017045161564725113"/>
         <inertia ixx="4.089294671130922e-08" iyy="3.323975046971373e-08" izz="2.9482536116204133e-08" ixy="0" ixz="0" iyz="0"/>
      </inertial>
      <visual name="index_um">
         <origin xyz="0.0003158098365906876 -0.00022882513673609314 -0.0036213650800712305" rpy="3.11344183213456 -1.2906456267839206 -3.102620114783569"/>
         <geometry>
            <mesh filename="package://viz/models/URDF_Simulation/converted_index_um.stl"/>
         </geometry>
         <material name="white"/>
      </visual>
   </link>
   <link name="index_abd_jointbody">
      <inertial>
         <origin xyz="0.0 0.0 0.0" rpy="0.0 0.0 0.0"/>
         <mass value="0.001"/>
         <inertia ixx="1e-09" iyy="1e-09" izz="1e-09" ixy="0" ixz="0" iyz="0"/>
      </inertial>
   </link>
   <joint type="revolute" name="index_abd">
      <parent link="index_um_virt"/>
      <child link="index_abd_jointbody"/>
      <origin xyz="0.0 0.0 0.018" rpy="0.0 0.0 0.0"/>
      <axis xyz="1.0 0.0 0.0"/>
      <limit lower="-0.264" upper="0.264" effort="100" velocity="100"/>
   </joint>
   <joint type="fixed" name="index_abd_offset">
      <parent link="index_abd_jointbody"/>
      <child link="index_um"/>
      <origin xyz="-0.0 -0.0 -0.0" rpy="0.0 0.0 0.0"/>
   </joint>
   <link name="index_pp_virt">
      <inertial>
         <origin xyz="0.0 0.0 0.0" rpy="0.0 0.0 0.0"/>
         <mass value="0.001"/>
         <inertia ixx="4e-10" iyy="4e-10" izz="3e-10" ixy="0" ixz="0" iyz="0"/>
      </inertial>
   </link>
   <link name="root2index_pp_virt_jointbody">
      <inertial>
         <origin xyz="0.0 0.0 0.0" rpy="0.0 0.0 0.0"/>
         <mass value="0.001"/>
         <inertia ixx="1e-09" iyy="1e-09" izz="1e-09" ixy="0" ixz="0" iyz="0"/>
      </inertial>
   </link>
   <joint type="revolute" name="root2index_pp_virt">
      <parent link="index_um"/>
      <child link="root2index_pp_virt_jointbody"/>
      <origin xyz="0.00270000102 5.9952065978308155e-19 -0.00743303472" rpy="0.0 0.0 -1.5707963267948963"/>
      <axis xyz="1.0 0.0 0.0"/>
      <limit lower="-0.157" upper="0.829" effort="100" velocity="100"/>
   </joint>
   <joint type="fixed" name="root2index_pp_virt_offset">
      <parent link="root2index_pp_virt_jointbody"/>
      <child link="index_pp_virt"/>
      <origin xyz="-0.0 -0.00270000102 -0.0" rpy="0.0 0.0 0.0"/>
   </joint>
   <link name="index_pp">
      <inertial>
         <origin xyz="0.0001596722768568773 0.0010995555377848291 0.01288169966540817" rpy="-0.0005635947558751964 0.04346039485505382 1.5731856208599835"/>
         <mass value="0.006934011983539235"/>
         <inertia ixx="1.1618492939118344e-06" iyy="1.1338221765005137e-06" izz="1.5329642762575548e-07" ixy="0" ixz="0" iyz="0"/>
      </inertial>
      <visual name="index_pp">
         <origin xyz="0.0001596722768568773 0.0010995555377848291 0.01288169966540817" rpy="-0.0005635947558753074 0.0434603948550536 1.5731856208599835"/>
         <geometry>
            <mesh filename="package://viz/models/URDF_Simulation/converted_index_pp.stl"/>
         </geometry>
         <material name="white"/>
      </visual>
   </link>
   <link name="root2index_pp_jointbody">
      <inertial>
         <origin xyz="0.0 0.0 0.0" rpy="0.0 0.0 0.0"/>
         <mass value="0.001"/>
         <inertia ixx="1e-09" iyy="1e-09" izz="1e-09" ixy="0" ixz="0" iyz="0"/>
      </inertial>
   </link>
   <joint type="revolute" name="root2index_pp">
      <parent link="index_pp_virt"/>
      <child link="root2index_pp_jointbody"/>
      <origin xyz="0.0 0.00250000102 0.018" rpy="0.0 0.0 0.0"/>
      <axis xyz="1.0 0.0 0.0"/>
      <limit lower="-0.157" upper="0.829" effort="100" velocity="100"/>
   </joint>
   <joint type="fixed" name="root2index_pp_offset">
      <parent link="root2index_pp_jointbody"/>
      <child link="index_pp"/>
      <origin xyz="-0.0 -0.00250000102 -0.0" rpy="0.0 0.0 0.0"/>
   </joint>
   <link name="index_pp_sens">
      <inertial>
         <origin xyz="0.0 -0.004 0.018" rpy="0.0 0.0 0.0"/>
         <mass value="0.0"/>
         <inertia ixx="0.0" iyy="0.0" izz="0.0" ixy="0" ixz="0" iyz="0"/>
      </inertial>
   </link>
   <link name="index_pp2index_pp_sens_fixed_jointbody">
      <inertial>
         <origin xyz="0.0 0.0 0.0" rpy="0.0 0.0 0.0"/>
         <mass value="0.001"/>
         <inertia ixx="1e-09" iyy="1e-09" izz="1e-09" ixy="0" ixz="0" iyz="0"/>
      </inertial>
   </link>
   <joint type="fixed" name="index_pp2index_pp_sens_fixed">
      <parent link="index_pp"/>
      <child link="index_pp2index_pp_sens_fixed_jointbody"/>
      <origin xyz="0.0 -0.004 0.018" rpy="0.0 0.0 0.0"/>
   </joint>
   <joint type="fixed" name="index_pp2index_pp_sens_fixed_offset">
      <parent link="index_pp2index_pp_sens_fixed_jointbody"/>
      <child link="index_pp_sens"/>
      <origin xyz="-0.0 -0.0 -0.0" rpy="0.0 0.0 0.0"/>
   </joint>
   <link name="index_mp_virt">
      <inertial>
         <origin xyz="0.0 0.0 0.0" rpy="0.0 0.0 0.0"/>
         <mass value="0.001"/>
         <inertia ixx="4e-10" iyy="4e-10" izz="3e-10" ixy="0" ixz="0" iyz="0"/>
      </inertial>
   </link>
   <link name="index_pp2mp_virt_jointbody">
      <inertial>
         <origin xyz="0.0 0.0 0.0" rpy="0.0 0.0 0.0"/>
         <mass value="0.001"/>
         <inertia ixx="1e-09" iyy="1e-09" izz="1e-09" ixy="0" ixz="0" iyz="0"/>
      </inertial>
   </link>
   <joint type="revolute" name="index_pp2mp_virt">
      <parent link="index_pp"/>
      <child link="index_pp2mp_virt_jointbody"/>
      <origin xyz="0.0 0.00370000102 0.03101612481" rpy="0.0 0.0 0.0"/>
      <axis xyz="1.0 0.0 0.0"/>
      <limit lower="-0.131" upper="0.96" effort="100" velocity="100"/>
   </joint>
   <joint type="fixed" name="index_pp2mp_virt_offset">
      <parent link="index_pp2mp_virt_jointbody"/>
      <child link="index_mp_virt"/>
      <origin xyz="-0.0 -0.00370000102 -0.0" rpy="0.0 0.0 0.0"/>
   </joint>
   <link name="index_mp">
      <inertial>
         <origin xyz="0.00011615953600365228 0.002416765310794026 0.01109535507776531" rpy="0.005169070242558416 0.005498569028424383 1.568902720116945"/>
         <mass value="0.00391743874952473"/>
         <inertia ixx="3.710686435522325e-07" iyy="3.400719694509783e-07" izz="7.116706680564789e-08" ixy="0" ixz="0" iyz="0"/>
      </inertial>
      <visual name="index_mp">
         <origin xyz="0.00011615953600365228 0.002416765310794026 0.01109535507776531" rpy="0.005169070242558416 0.005498569028424383 1.568902720116945"/>
         <geometry>
            <mesh filename="package://viz/models/URDF_Simulation/converted_index_mp.stl"/>
         </geometry>
         <material name="white"/>
      </visual>
   </link>
   <link name="index_pp2mp_jointbody">
      <inertial>
         <origin xyz="0.0 0.0 0.0" rpy="0.0 0.0 0.0"/>
         <mass value="0.001"/>
         <inertia ixx="1e-09" iyy="1e-09" izz="1e-09" ixy="0" ixz="0" iyz="0"/>
      </inertial>
   </link>
   <joint type="revolute" name="index_pp2mp">
      <parent link="index_mp_virt"/>
      <child link="index_pp2mp_jointbody"/>
      <origin xyz="0.0 0.00350000102 0.012" rpy="0.0 0.0 0.0"/>
      <axis xyz="1.0 0.0 0.0"/>
      <limit lower="-0.131" upper="0.96" effort="100" velocity="100"/>
   </joint>
   <joint type="fixed" name="index_pp2mp_offset">
      <parent link="index_pp2mp_jointbody"/>
      <child link="index_mp"/>
      <origin xyz="-0.0 -0.00350000102 -0.0" rpy="0.0 0.0 0.0"/>
   </joint>
   <link name="index_dp_virt">
      <inertial>
         <origin xyz="0.0 0.0 0.0" rpy="0.0 0.0 0.0"/>
         <mass value="0.001"/>
         <inertia ixx="4e-10" iyy="4e-10" izz="3e-10" ixy="0" ixz="0" iyz="0"/>
      </inertial>
   </link>
   <link name="index_mp2dp_virt_jointbody">
      <inertial>
         <origin xyz="0.0 0.0 0.0" rpy="0.0 0.0 0.0"/>
         <mass value="0.001"/>
         <inertia ixx="1e-09" iyy="1e-09" izz="1e-09" ixy="0" ixz="0" iyz="0"/>
      </inertial>
   </link>
   <joint type="revolute" name="index_mp2dp_virt">
      <parent link="index_mp"/>
      <child link="index_mp2dp_virt_jointbody"/>
      <origin xyz="0.0 0.00370000102 0.0235" rpy="0.0 0.0 0.0"/>
      <axis xyz="1.0 0.0 0.0"/>
      <limit lower="-0.093" upper="0.682" effort="100" velocity="100"/>
   </joint>
   <joint type="fixed" name="index_mp2dp_virt_offset">
      <parent link="index_mp2dp_virt_jointbody"/>
      <child link="index_dp_virt"/>
      <origin xyz="-0.0 -0.00370000102 -0.0" rpy="0.0 0.0 0.0"/>
   </joint>
   <link name="index_dp">
      <inertial>
         <origin xyz="0.00011951811090689032 0.003120678557622198 0.007573116228122234" rpy="-0.001893780008492163 0.05085216250260771 1.5852087171365512"/>
         <mass value="0.0021639273972605794"/>
         <inertia ixx="1.0745931609543126e-07" iyy="9.222697287325353e-08" izz="2.9490220566203e-08" ixy="0" ixz="0" iyz="0"/>
      </inertial>
      <visual name="index_dp">
         <origin xyz="0.00011951811090689032 0.003120678557622198 0.007573116228122234" rpy="-0.001893780008492163 0.05085216250260771 1.5852087171365514"/>
         <geometry>
            <mesh filename="package://viz/models/URDF_Simulation/converted_index_dp.stl"/>
         </geometry>
         <material name="white"/>
      </visual>
   </link>
   <link name="index_mp2dp_jointbody">
      <inertial>
         <origin xyz="0.0 0.0 0.0" rpy="0.0 0.0 0.0"/>
         <mass value="0.001"/>
         <inertia ixx="1e-09" iyy="1e-09" izz="1e-09" ixy="0" ixz="0" iyz="0"/>
      </inertial>
   </link>
   <joint type="revolute" name="index_mp2dp">
      <parent link="index_dp_virt"/>
      <child link="index_mp2dp_jointbody"/>
      <origin xyz="0.0 0.00350000102 0.009" rpy="0.0 0.0 0.0"/>
      <axis xyz="1.0 0.0 0.0"/>
      <limit lower="-0.093" upper="0.682" effort="100" velocity="100"/>
   </joint>
   <joint type="fixed" name="index_mp2dp_offset">
      <parent link="index_mp2dp_jointbody"/>
      <child link="index_dp"/>
      <origin xyz="-0.0 -0.00350000102 -0.0" rpy="0.0 0.0 0.0"/>
   </joint>
   <link name="index_fingertip">
      <inertial>
         <origin xyz="0.0 0.0 0.01" rpy="0.0 0.0 0.0"/>
         <mass value="0.0"/>
         <inertia ixx="0.0" iyy="0.0" izz="0.0" ixy="0" ixz="0" iyz="0"/>
      </inertial>
   </link>
   <link name="index_dp2index_fingertip_fixed_jointbody">
      <inertial>
         <origin xyz="0.0 0.0 0.0" rpy="0.0 0.0 0.0"/>
         <mass value="0.001"/>
         <inertia ixx="1e-09" iyy="1e-09" izz="1e-09" ixy="0" ixz="0" iyz="0"/>
      </inertial>
   </link>
   <joint type="fixed" name="index_dp2index_fingertip_fixed">
      <parent link="index_dp"/>
      <child link="index_dp2index_fingertip_fixed_jointbody"/>
      <origin xyz="0.0 0.0 0.01" rpy="0.0 0.0 0.0"/>
   </joint>
   <joint type="fixed" name="index_dp2index_fingertip_fixed_offset">
      <parent link="index_dp2index_fingertip_fixed_jointbody"/>
      <child link="index_fingertip"/>
      <origin xyz="-0.0 -0.0 -0.0" rpy="0.0 0.0 0.0"/>
   </joint>
   <link name="middle_um_virt">
      <inertial>
         <origin xyz="0.0 0.0 0.0" rpy="0.0 0.0 0.0"/>
         <mass value="0.001"/>
         <inertia ixx="4e-10" iyy="4e-10" izz="3e-10" ixy="0" ixz="0" iyz="0"/>
      </inertial>
   </link>
   <link name="middle_abd_virt_jointbody">
      <inertial>
         <origin xyz="0.0 0.0 0.0" rpy="0.0 0.0 0.0"/>
         <mass value="0.001"/>
         <inertia ixx="1e-09" iyy="1e-09" izz="1e-09" ixy="0" ixz="0" iyz="0"/>
      </inertial>
   </link>
   <joint type="revolute" name="middle_abd_virt">
      <parent link="palm"/>
      <child link="middle_abd_virt_jointbody"/>
      <origin xyz="0.0036 0.0886 0.0" rpy="-1.5707963267948966 1.5707963267948966 0.0"/>
      <axis xyz="1.0 0.0 0.0"/>
      <limit lower="-0.264" upper="0.264" effort="100" velocity="100"/>
   </joint>
   <joint type="fixed" name="middle_abd_virt_offset">
      <parent link="middle_abd_virt_jointbody"/>
      <child link="middle_um_virt"/>
      <origin xyz="-0.0 -0.0 -0.0" rpy="0.0 0.0 0.0"/>
   </joint>
   <link name="middle_um">
      <inertial>
         <origin xyz="0.0003169177085226183 -4.3580464142454146e-05 -0.00358903262860973" rpy="3.1142767042476764 -1.2906066346792464 -3.101151560580364"/>
         <mass value="0.0017047365062490877"/>
         <inertia ixx="4.089764222360987e-08" iyy="3.324524824350021e-08" izz="2.9498620771363934e-08" ixy="0" ixz="0" iyz="0"/>
      </inertial>
      <visual name="middle_um">
         <origin xyz="0.0003169177085226183 -4.3580464142454146e-05 -0.00358903262860973" rpy="3.1142767042476764 -1.2906066346792464 -3.101151560580364"/>
         <geometry>
            <mesh filename="package://viz/models/URDF_Simulation/converted_middle_um.stl"/>
         </geometry>
         <material name="white"/>
      </visual>
   </link>
   <link name="middle_abd_jointbody">
      <inertial>
         <origin xyz="0.0 0.0 0.0" rpy="0.0 0.0 0.0"/>
         <mass value="0.001"/>
         <inertia ixx="1e-09" iyy="1e-09" izz="1e-09" ixy="0" ixz="0" iyz="0"/>
      </inertial>
   </link>
   <joint type="revolute" name="middle_abd">
      <parent link="middle_um_virt"/>
      <child link="middle_abd_jointbody"/>
      <origin xyz="0.0 0.0 0.018" rpy="0.0 0.0 0.0"/>
      <axis xyz="1.0 0.0 0.0"/>
      <limit lower="-0.264" upper="0.264" effort="100" velocity="100"/>
   </joint>
   <joint type="fixed" name="middle_abd_offset">
      <parent link="middle_abd_jointbody"/>
      <child link="middle_um"/>
      <origin xyz="-0.0 -0.0 -0.0" rpy="0.0 0.0 0.0"/>
   </joint>
   <link name="middle_pp_virt">
      <inertial>
         <origin xyz="0.0 0.0 0.0" rpy="0.0 0.0 0.0"/>
         <mass value="0.001"/>
         <inertia ixx="4e-10" iyy="4e-10" izz="3e-10" ixy="0" ixz="0" iyz="0"/>
      </inertial>
   </link>
   <link name="root2middle_pp_virt_jointbody">
      <inertial>
         <origin xyz="0.0 0.0 0.0" rpy="0.0 0.0 0.0"/>
         <mass value="0.001"/>
         <inertia ixx="1e-09" iyy="1e-09" izz="1e-09" ixy="0" ixz="0" iyz="0"/>
      </inertial>
   </link>
   <joint type="revolute" name="root2middle_pp_virt">
      <parent link="middle_um"/>
      <child link="root2middle_pp_virt_jointbody"/>
      <origin xyz="0.002700001023199999 5.99520660493624e-19 -0.00743303472" rpy="0.0 0.0 -1.5707963267948963"/>
      <axis xyz="1.0 0.0 0.0"/>
      <limit lower="-0.157" upper="0.829" effort="100" velocity="100"/>
   </joint>
   <joint type="fixed" name="root2middle_pp_virt_offset">
      <parent link="root2middle_pp_virt_jointbody"/>
      <child link="middle_pp_virt"/>
      <origin xyz="-0.0 -0.002700001023199999 -0.0" rpy="0.0 0.0 0.0"/>
   </joint>
   <link name="middle_pp">
      <inertial>
         <origin xyz="-2.677702921494884e-05 0.0012083795875931697 0.014736324701324952" rpy="-0.0005735052637568794 0.04126377469973974 1.57485854430987"/>
         <mass value="0.007431440532107334"/>
         <inertia ixx="1.4952081907729184e-06" iyy="1.4626277055074752e-06" izz="1.6114556634419006e-07" ixy="0" ixz="0" iyz="0"/>
      </inertial>
      <visual name="middle_pp">
         <origin xyz="-2.677702921494884e-05 0.0012083795875931697 0.014736324701324952" rpy="-0.0005735052637568794 0.041263774699739963 1.57485854430987"/>
         <geometry>
            <mesh filename="package://viz/models/URDF_Simulation/converted_middle_pp.stl"/>
         </geometry>
         <material name="white"/>
      </visual>
   </link>
   <link name="root2middle_pp_jointbody">
      <inertial>
         <origin xyz="0.0 0.0 0.0" rpy="0.0 0.0 0.0"/>
         <mass value="0.001"/>
         <inertia ixx="1e-09" iyy="1e-09" izz="1e-09" ixy="0" ixz="0" iyz="0"/>
      </inertial>
   </link>
   <joint type="revolute" name="root2middle_pp">
      <parent link="middle_pp_virt"/>
      <child link="root2middle_pp_jointbody"/>
      <origin xyz="0.0 0.002500001023199999 0.018" rpy="0.0 0.0 0.0"/>
      <axis xyz="1.0 0.0 0.0"/>
      <limit lower="-0.157" upper="0.829" effort="100" velocity="100"/>
   </joint>
   <joint type="fixed" name="root2middle_pp_offset">
      <parent link="root2middle_pp_jointbody"/>
      <child link="middle_pp"/>
      <origin xyz="-0.0 -0.002500001023199999 -0.0" rpy="0.0 0.0 0.0"/>
   </joint>
   <link name="middle_pp_sens">
      <inertial>
         <origin xyz="0.0 -0.004 0.022" rpy="0.0 0.0 0.0"/>
         <mass value="0.0"/>
         <inertia ixx="0.0" iyy="0.0" izz="0.0" ixy="0" ixz="0" iyz="0"/>
      </inertial>
   </link>
   <link name="middle_pp2middle_pp_sens_fixed_jointbody">
      <inertial>
         <origin xyz="0.0 0.0 0.0" rpy="0.0 0.0 0.0"/>
         <mass value="0.001"/>
         <inertia ixx="1e-09" iyy="1e-09" izz="1e-09" ixy="0" ixz="0" iyz="0"/>
      </inertial>
   </link>
   <joint type="fixed" name="middle_pp2middle_pp_sens_fixed">
      <parent link="middle_pp"/>
      <child link="middle_pp2middle_pp_sens_fixed_jointbody"/>
      <origin xyz="0.0 -0.004 0.022" rpy="0.0 0.0 0.0"/>
   </joint>
   <joint type="fixed" name="middle_pp2middle_pp_sens_fixed_offset">
      <parent link="middle_pp2middle_pp_sens_fixed_jointbody"/>
      <child link="middle_pp_sens"/>
      <origin xyz="-0.0 -0.0 -0.0" rpy="0.0 0.0 0.0"/>
   </joint>
   <link name="middle_mp_virt">
      <inertial>
         <origin xyz="0.0 0.0 0.0" rpy="0.0 0.0 0.0"/>
         <mass value="0.001"/>
         <inertia ixx="4e-10" iyy="4e-10" izz="3e-10" ixy="0" ixz="0" iyz="0"/>
      </inertial>
   </link>
   <link name="middle_pp2mp_virt_jointbody">
      <inertial>
         <origin xyz="0.0 0.0 0.0" rpy="0.0 0.0 0.0"/>
         <mass value="0.001"/>
         <inertia ixx="1e-09" iyy="1e-09" izz="1e-09" ixy="0" ixz="0" iyz="0"/>
      </inertial>
   </link>
   <joint type="revolute" name="middle_pp2mp_virt">
      <parent link="middle_pp"/>
      <child link="middle_pp2mp_virt_jointbody"/>
      <origin xyz="0.0 0.0037000000000999996 0.03501428277" rpy="0.0 0.0 0.0"/>
      <axis xyz="1.0 0.0 0.0"/>
      <limit lower="-0.131" upper="0.96" effort="100" velocity="100"/>
   </joint>
   <joint type="fixed" name="middle_pp2mp_virt_offset">
      <parent link="middle_pp2mp_virt_jointbody"/>
      <child link="middle_mp_virt"/>
      <origin xyz="-0.0 -0.0037000000000999996 -0.0" rpy="0.0 0.0 0.0"/>
   </joint>
   <link name="middle_mp">
      <inertial>
         <origin xyz="-7.28956068113046e-05 0.002462634567765748 0.01217139362029477" rpy="0.004902958340904706 0.004923370489530621 1.569477804197481"/>
         <mass value="0.004122015435614137"/>
         <inertia ixx="4.381415089977954e-07" iyy="4.050525829693079e-07" izz="7.452990013142263e-08" ixy="0" ixz="0" iyz="0"/>
      </inertial>
      <visual name="middle_mp">
         <origin xyz="-7.28956068113046e-05 0.002462634567765748 0.01217139362029477" rpy="0.004902958340904706 0.004923370489530621 1.569477804197481"/>
         <geometry>
            <mesh filename="package://viz/models/URDF_Simulation/converted_middle_mp.stl"/>
         </geometry>
         <material name="white"/>
      </visual>
   </link>
   <link name="middle_pp2mp_jointbody">
      <inertial>
         <origin xyz="0.0 0.0 0.0" rpy="0.0 0.0 0.0"/>
         <mass value="0.001"/>
         <inertia ixx="1e-09" iyy="1e-09" izz="1e-09" ixy="0" ixz="0" iyz="0"/>
      </inertial>
   </link>
   <joint type="revolute" name="middle_pp2mp">
      <parent link="middle_mp_virt"/>
      <child link="middle_pp2mp_jointbody"/>
      <origin xyz="0.0 0.0035000000000999995 0.012" rpy="0.0 0.0 0.0"/>
      <axis xyz="1.0 0.0 0.0"/>
      <limit lower="-0.131" upper="0.96" effort="100" velocity="100"/>
   </joint>
   <joint type="fixed" name="middle_pp2mp_offset">
      <parent link="middle_pp2mp_jointbody"/>
      <child link="middle_mp"/>
      <origin xyz="-0.0 -0.0035000000000999995 -0.0" rpy="0.0 0.0 0.0"/>
   </joint>
   <link name="middle_dp_virt">
      <inertial>
         <origin xyz="0.0 0.0 0.0" rpy="0.0 0.0 0.0"/>
         <mass value="0.001"/>
         <inertia ixx="4e-10" iyy="4e-10" izz="3e-10" ixy="0" ixz="0" iyz="0"/>
      </inertial>
   </link>
   <link name="middle_mp2dp_virt_jointbody">
      <inertial>
         <origin xyz="0.0 0.0 0.0" rpy="0.0 0.0 0.0"/>
         <mass value="0.001"/>
         <inertia ixx="1e-09" iyy="1e-09" izz="1e-09" ixy="0" ixz="0" iyz="0"/>
      </inertial>
   </link>
   <joint type="revolute" name="middle_mp2dp_virt">
      <parent link="middle_mp"/>
      <child link="middle_mp2dp_virt_jointbody"/>
      <origin xyz="0.0 0.0037000000000999996 0.0255" rpy="0.0 0.0 0.0"/>
      <axis xyz="1.0 0.0 0.0"/>
      <limit lower="-0.093" upper="0.682" effort="100" velocity="100"/>
   </joint>
   <joint type="fixed" name="middle_mp2dp_virt_offset">
      <parent link="middle_mp2dp_virt_jointbody"/>
      <child link="middle_dp_virt"/>
      <origin xyz="-0.0 -0.0037000000000999996 -0.0" rpy="0.0 0.0 0.0"/>
   </joint>
   <link name="middle_dp">
      <inertial>
         <origin xyz="3.0280177180663673e-05 0.0031179204392796566 0.0076814262845085746" rpy="0.00823787222220096 0.050673311372765095 1.5580538179925818"/>
         <mass value="0.002165187096269976"/>
         <inertia ixx="1.0756444680126282e-07" iyy="9.22710567268227e-08" izz="2.9564221225540638e-08" ixy="0" ixz="0" iyz="0"/>
      </inertial>
      <visual name="middle_dp">
         <origin xyz="3.0280177180663673e-05 0.0031179204392796566 0.0076814262845085746" rpy="0.00823787222220096 0.050673311372765095 1.5580538179925818"/>
         <geometry>
            <mesh filename="package://viz/models/URDF_Simulation/converted_middle_dp.stl"/>
         </geometry>
         <material name="white"/>
      </visual>
   </link>
   <link name="middle_mp2dp_jointbody">
      <inertial>
         <origin xyz="0.0 0.0 0.0" rpy="0.0 0.0 0.0"/>
         <mass value="0.001"/>
         <inertia ixx="1e-09" iyy="1e-09" izz="1e-09" ixy="0" ixz="0" iyz="0"/>
      </inertial>
   </link>
   <joint type="revolute" name="middle_mp2dp">
      <parent link="middle_dp_virt"/>
      <child link="middle_mp2dp_jointbody"/>
      <origin xyz="0.0 0.0035000000000999995 0.009" rpy="0.0 0.0 0.0"/>
      <axis xyz="1.0 0.0 0.0"/>
      <limit lower="-0.093" upper="0.682" effort="100" velocity="100"/>
   </joint>
   <joint type="fixed" name="middle_mp2dp_offset">
      <parent link="middle_mp2dp_jointbody"/>
      <child link="middle_dp"/>
      <origin xyz="-0.0 -0.0035000000000999995 -0.0" rpy="0.0 0.0 0.0"/>
   </joint>
   <link name="middle_fingertip">
      <inertial>
         <origin xyz="0.0 0.0 0.01" rpy="0.0 0.0 0.0"/>
         <mass value="0.0"/>
         <inertia ixx="0.0" iyy="0.0" izz="0.0" ixy="0" ixz="0" iyz="0"/>
      </inertial>
   </link>
   <link name="middle_dp2middle_fingertip_fixed_jointbody">
      <inertial>
         <origin xyz="0.0 0.0 0.0" rpy="0.0 0.0 0.0"/>
         <mass value="0.001"/>
         <inertia ixx="1e-09" iyy="1e-09" izz="1e-09" ixy="0" ixz="0" iyz="0"/>
      </inertial>
   </link>
   <joint type="fixed" name="middle_dp2middle_fingertip_fixed">
      <parent link="middle_dp"/>
      <child link="middle_dp2middle_fingertip_fixed_jointbody"/>
      <origin xyz="0.0 0.0 0.01" rpy="0.0 0.0 0.0"/>
   </joint>
   <joint type="fixed" name="middle_dp2middle_fingertip_fixed_offset">
      <parent link="middle_dp2middle_fingertip_fixed_jointbody"/>
      <child link="middle_fingertip"/>
      <origin xyz="-0.0 -0.0 -0.0" rpy="0.0 0.0 0.0"/>
   </joint>
   <link name="ring_um_virt">
      <inertial>
         <origin xyz="0.0 0.0 0.0" rpy="0.0 0.0 0.0"/>
         <mass value="0.001"/>
         <inertia ixx="4e-10" iyy="4e-10" izz="3e-10" ixy="0" ixz="0" iyz="0"/>
      </inertial>
   </link>
   <link name="ring_abd_virt_jointbody">
      <inertial>
         <origin xyz="0.0 0.0 0.0" rpy="0.0 0.0 0.0"/>
         <mass value="0.001"/>
         <inertia ixx="1e-09" iyy="1e-09" izz="1e-09" ixy="0" ixz="0" iyz="0"/>
      </inertial>
   </link>
   <joint type="revolute" name="ring_abd_virt">
      <parent link="palm"/>
      <child link="ring_abd_virt_jointbody"/>
      <origin xyz="-0.017817999999999997 0.0852 0.0" rpy="-1.5707963267948966 1.5707963267948966 0.0"/>
      <axis xyz="1.0 0.0 0.0"/>
      <limit lower="-0.264" upper="0.264" effort="100" velocity="100"/>
   </joint>
   <joint type="fixed" name="ring_abd_virt_offset">
      <parent link="ring_abd_virt_jointbody"/>
      <child link="ring_um_virt"/>
      <origin xyz="-0.0 -0.0 -0.0" rpy="0.0 0.0 0.0"/>
   </joint>
   <link name="ring_um">
      <inertial>
         <origin xyz="0.00031526315659068625 -4.483507673610013e-05 -0.0035895413100712256" rpy="3.1134418321345594 -1.2906456267839208 -3.1026201147835684"/>
         <mass value="0.0017045161564725113"/>
         <inertia ixx="4.089294671130922e-08" iyy="3.323975046971373e-08" izz="2.9482536116204133e-08" ixy="0" ixz="0" iyz="0"/>
      </inertial>
      <visual name="ring_um">
         <origin xyz="0.00031526315659068625 -4.483507673610013e-05 -0.0035895413100712256" rpy="3.11344183213456 -1.2906456267839206 -3.102620114783569"/>
         <geometry>
            <mesh filename="package://viz/models/URDF_Simulation/converted_ring_um.stl"/>
         </geometry>
         <material name="white"/>
      </visual>
   </link>
   <link name="ring_abd_jointbody">
      <inertial>
         <origin xyz="0.0 0.0 0.0" rpy="0.0 0.0 0.0"/>
         <mass value="0.001"/>
         <inertia ixx="1e-09" iyy="1e-09" izz="1e-09" ixy="0" ixz="0" iyz="0"/>
      </inertial>
   </link>
   <joint type="revolute" name="ring_abd">
      <parent link="ring_um_virt"/>
      <child link="ring_abd_jointbody"/>
      <origin xyz="0.0 0.0 0.018" rpy="0.0 0.0 0.0"/>
      <axis xyz="1.0 0.0 0.0"/>
      <limit lower="-0.264" upper="0.264" effort="100" velocity="100"/>
   </joint>
   <joint type="fixed" name="ring_abd_offset">
      <parent link="ring_abd_jointbody"/>
      <child link="ring_um"/>
      <origin xyz="-0.0 -0.0 -0.0" rpy="0.0 0.0 0.0"/>
   </joint>
   <link name="ring_pp_virt">
      <inertial>
         <origin xyz="0.0 0.0 0.0" rpy="0.0 0.0 0.0"/>
         <mass value="0.001"/>
         <inertia ixx="4e-10" iyy="4e-10" izz="3e-10" ixy="0" ixz="0" iyz="0"/>
      </inertial>
   </link>
   <link name="root2ring_pp_virt_jointbody">
      <inertial>
         <origin xyz="0.0 0.0 0.0" rpy="0.0 0.0 0.0"/>
         <mass value="0.001"/>
         <inertia ixx="1e-09" iyy="1e-09" izz="1e-09" ixy="0" ixz="0" iyz="0"/>
      </inertial>
   </link>
   <joint type="revolute" name="root2ring_pp_virt">
      <parent link="ring_um"/>
      <child link="root2ring_pp_virt_jointbody"/>
      <origin xyz="0.002700001023199999 5.99520660493624e-19 -0.00743303472" rpy="0.0 0.0 -1.5707963267948963"/>
      <axis xyz="1.0 0.0 0.0"/>
      <limit lower="-0.157" upper="0.829" effort="100" velocity="100"/>
   </joint>
   <joint type="fixed" name="root2ring_pp_virt_offset">
      <parent link="root2ring_pp_virt_jointbody"/>
      <child link="ring_pp_virt"/>
      <origin xyz="-0.0 -0.002700001023199999 -0.0" rpy="0.0 0.0 0.0"/>
   </joint>
   <link name="ring_pp">
      <inertial>
         <origin xyz="-2.4317783143122662e-05 0.0010990088577848291 0.012970488715408169" rpy="-0.0005635947558751964 0.04346039485505382 1.5731856208599835"/>
         <mass value="0.006934011983539235"/>
         <inertia ixx="1.1618492939118344e-06" iyy="1.1338221765005137e-06" izz="1.5329642762575548e-07" ixy="0" ixz="0" iyz="0"/>
      </inertial>
      <visual name="ring_pp">
         <origin xyz="-2.4317783143122662e-05 0.0010990088577848291 0.012970488715408169" rpy="-0.0005635947558753074 0.0434603948550536 1.5731856208599835"/>
         <geometry>
            <mesh filename="package://viz/models/URDF_Simulation/converted_ring_pp.stl"/>
         </geometry>
         <material name="white"/>
      </visual>
   </link>
   <link name="root2ring_pp_jointbody">
      <inertial>
         <origin xyz="0.0 0.0 0.0" rpy="0.0 0.0 0.0"/>
         <mass value="0.001"/>
         <inertia ixx="1e-09" iyy="1e-09" izz="1e-09" ixy="0" ixz="0" iyz="0"/>
      </inertial>
   </link>
   <joint type="revolute" name="root2ring_pp">
      <parent link="ring_pp_virt"/>
      <child link="root2ring_pp_jointbody"/>
      <origin xyz="0.0 0.002500001023199999 0.018" rpy="0.0 0.0 0.0"/>
      <axis xyz="1.0 0.0 0.0"/>
      <limit lower="-0.157" upper="0.829" effort="100" velocity="100"/>
   </joint>
   <joint type="fixed" name="root2ring_pp_offset">
      <parent link="root2ring_pp_jointbody"/>
      <child link="ring_pp"/>
      <origin xyz="-0.0 -0.002500001023199999 -0.0" rpy="0.0 0.0 0.0"/>
   </joint>
   <link name="ring_pp_sens">
      <inertial>
         <origin xyz="0.0 -0.004 0.018" rpy="0.0 0.0 0.0"/>
         <mass value="0.0"/>
         <inertia ixx="0.0" iyy="0.0" izz="0.0" ixy="0" ixz="0" iyz="0"/>
      </inertial>
   </link>
   <link name="ring_pp2ring_pp_sens_fixed_jointbody">
      <inertial>
         <origin xyz="0.0 0.0 0.0" rpy="0.0 0.0 0.0"/>
         <mass value="0.001"/>
         <inertia ixx="1e-09" iyy="1e-09" izz="1e-09" ixy="0" ixz="0" iyz="0"/>
      </inertial>
   </link>
   <joint type="fixed" name="ring_pp2ring_pp_sens_fixed">
      <parent link="ring_pp"/>
      <child link="ring_pp2ring_pp_sens_fixed_jointbody"/>
      <origin xyz="0.0 -0.004 0.018" rpy="0.0 0.0 0.0"/>
   </joint>
   <joint type="fixed" name="ring_pp2ring_pp_sens_fixed_offset">
      <parent link="ring_pp2ring_pp_sens_fixed_jointbody"/>
      <child link="ring_pp_sens"/>
      <origin xyz="-0.0 -0.0 -0.0" rpy="0.0 0.0 0.0"/>
   </joint>
   <link name="ring_mp_virt">
      <inertial>
         <origin xyz="0.0 0.0 0.0" rpy="0.0 0.0 0.0"/>
         <mass value="0.001"/>
         <inertia ixx="4e-10" iyy="4e-10" izz="3e-10" ixy="0" ixz="0" iyz="0"/>
      </inertial>
   </link>
   <link name="ring_pp2mp_virt_jointbody">
      <inertial>
         <origin xyz="0.0 0.0 0.0" rpy="0.0 0.0 0.0"/>
         <mass value="0.001"/>
         <inertia ixx="1e-09" iyy="1e-09" izz="1e-09" ixy="0" ixz="0" iyz="0"/>
      </inertial>
   </link>
   <joint type="revolute" name="ring_pp2mp_virt">
      <parent link="ring_pp"/>
      <child link="ring_pp2mp_virt_jointbody"/>
      <origin xyz="0.0 0.0037000000000999996 0.03101612481" rpy="0.0 0.0 0.0"/>
      <axis xyz="1.0 0.0 0.0"/>
      <limit lower="-0.131" upper="0.96" effort="100" velocity="100"/>
   </joint>
   <joint type="fixed" name="ring_pp2mp_virt_offset">
      <parent link="ring_pp2mp_virt_jointbody"/>
      <child link="ring_mp_virt"/>
      <origin xyz="-0.0 -0.0037000000000999996 -0.0" rpy="0.0 0.0 0.0"/>
   </joint>
   <link name="ring_mp">
      <inertial>
         <origin xyz="-6.783052399634767e-05 0.002416218630794026 0.011184144137765306" rpy="0.005169070242558416 0.005498569028424383 1.568902720116945"/>
         <mass value="0.00391743874952473"/>
         <inertia ixx="3.710686435522325e-07" iyy="3.400719694509783e-07" izz="7.116706680564789e-08" ixy="0" ixz="0" iyz="0"/>
      </inertial>
      <visual name="ring_mp">
         <origin xyz="-6.783052399634767e-05 0.002416218630794026 0.011184144137765306" rpy="0.005169070242558416 0.005498569028424383 1.568902720116945"/>
         <geometry>
            <mesh filename="package://viz/models/URDF_Simulation/converted_ring_mp.stl"/>
         </geometry>
         <material name="white"/>
      </visual>
   </link>
   <link name="ring_pp2mp_jointbody">
      <inertial>
         <origin xyz="0.0 0.0 0.0" rpy="0.0 0.0 0.0"/>
         <mass value="0.001"/>
         <inertia ixx="1e-09" iyy="1e-09" izz="1e-09" ixy="0" ixz="0" iyz="0"/>
      </inertial>
   </link>
   <joint type="revolute" name="ring_pp2mp">
      <parent link="ring_mp_virt"/>
      <child link="ring_pp2mp_jointbody"/>
      <origin xyz="0.0 0.0035000000000999995 0.012" rpy="0.0 0.0 0.0"/>
      <axis xyz="1.0 0.0 0.0"/>
      <limit lower="-0.131" upper="0.96" effort="100" velocity="100"/>
   </joint>
   <joint type="fixed" name="ring_pp2mp_offset">
      <parent link="ring_pp2mp_jointbody"/>
      <child link="ring_mp"/>
      <origin xyz="-0.0 -0.0035000000000999995 -0.0" rpy="0.0 0.0 0.0"/>
   </joint>
   <link name="ring_dp_virt">
      <inertial>
         <origin xyz="0.0 0.0 0.0" rpy="0.0 0.0 0.0"/>
         <mass value="0.001"/>
         <inertia ixx="4e-10" iyy="4e-10" izz="3e-10" ixy="0" ixz="0" iyz="0"/>
      </inertial>
   </link>
   <link name="ring_mp2dp_virt_jointbody">
      <inertial>
         <origin xyz="0.0 0.0 0.0" rpy="0.0 0.0 0.0"/>
         <mass value="0.001"/>
         <inertia ixx="1e-09" iyy="1e-09" izz="1e-09" ixy="0" ixz="0" iyz="0"/>
      </inertial>
   </link>
   <joint type="revolute" name="ring_mp2dp_virt">
      <parent link="ring_mp"/>
      <child link="ring_mp2dp_virt_jointbody"/>
      <origin xyz="0.0 0.0037000000000999996 0.0235" rpy="0.0 0.0 0.0"/>
      <axis xyz="1.0 0.0 0.0"/>
      <limit lower="-0.093" upper="0.682" effort="100" velocity="100"/>
   </joint>
   <joint type="fixed" name="ring_mp2dp_virt_offset">
      <parent link="ring_mp2dp_virt_jointbody"/>
      <child link="ring_dp_virt"/>
      <origin xyz="-0.0 -0.0037000000000999996 -0.0" rpy="0.0 0.0 0.0"/>
   </joint>
   <link name="ring_dp">
      <inertial>
         <origin xyz="-6.447194909310963e-05 0.003120131877622198 0.007661905288122245" rpy="-0.001893780008492163 0.05085216250260771 1.5852087171365512"/>
         <mass value="0.0021639273972605794"/>
         <inertia ixx="1.0745931609543126e-07" iyy="9.222697287325353e-08" izz="2.9490220566203e-08" ixy="0" ixz="0" iyz="0"/>
      </inertial>
      <visual name="ring_dp">
         <origin xyz="-6.447194909310963e-05 0.003120131877622198 0.007661905288122245" rpy="-0.001893780008492163 0.05085216250260771 1.5852087171365514"/>
         <geometry>
            <mesh filename="package://viz/models/URDF_Simulation/converted_ring_dp.stl"/>
         </geometry>
         <material name="white"/>
      </visual>
   </link>
   <link name="ring_mp2dp_jointbody">
      <inertial>
         <origin xyz="0.0 0.0 0.0" rpy="0.0 0.0 0.0"/>
         <mass value="0.001"/>
         <inertia ixx="1e-09" iyy="1e-09" izz="1e-09" ixy="0" ixz="0" iyz="0"/>
      </inertial>
   </link>
   <joint type="revolute" name="ring_mp2dp">
      <parent link="ring_dp_virt"/>
      <child link="ring_mp2dp_jointbody"/>
      <origin xyz="0.0 0.0035000000000999995 0.009" rpy="0.0 0.0 0.0"/>
      <axis xyz="1.0 0.0 0.0"/>
      <limit lower="-0.093" upper="0.682" effort="100" velocity="100"/>
   </joint>
   <joint type="fixed" name="ring_mp2dp_offset">
      <parent link="ring_mp2dp_jointbody"/>
      <child link="ring_dp"/>
      <origin xyz="-0.0 -0.0035000000000999995 -0.0" rpy="0.0 0.0 0.0"/>
   </joint>
   <link name="ring_fingertip">
      <inertial>
         <origin xyz="0.0 0.0 0.01" rpy="0.0 0.0 0.0"/>
         <mass value="0.0"/>
         <inertia ixx="0.0" iyy="0.0" izz="0.0" ixy="0" ixz="0" iyz="0"/>
      </inertial>
   </link>
   <link name="ring_dp2ring_fingertip_fixed_jointbody">
      <inertial>
         <origin xyz="0.0 0.0 0.0" rpy="0.0 0.0 0.0"/>
         <mass value="0.001"/>
         <inertia ixx="1e-09" iyy="1e-09" izz="1e-09" ixy="0" ixz="0" iyz="0"/>
      </inertial>
   </link>
   <joint type="fixed" name="ring_dp2ring_fingertip_fixed">
      <parent link="ring_dp"/>
      <child link="ring_dp2ring_fingertip_fixed_jointbody"/>
      <origin xyz="0.0 0.0 0.01" rpy="0.0 0.0 0.0"/>
   </joint>
   <joint type="fixed" name="ring_dp2ring_fingertip_fixed_offset">
      <parent link="ring_dp2ring_fingertip_fixed_jointbody"/>
      <child link="ring_fingertip"/>
      <origin xyz="-0.0 -0.0 -0.0" rpy="0.0 0.0 0.0"/>
   </joint>
   <link name="pinky_um_virt">
      <inertial>
         <origin xyz="0.0 0.0 0.0" rpy="0.0 0.0 0.0"/>
         <mass value="0.001"/>
         <inertia ixx="4e-10" iyy="4e-10" izz="3e-10" ixy="0" ixz="0" iyz="0"/>
      </inertial>
   </link>
   <link name="pinky_abd_virt_jointbody">
      <inertial>
         <origin xyz="0.0 0.0 0.0" rpy="0.0 0.0 0.0"/>
         <mass value="0.001"/>
         <inertia ixx="1e-09" iyy="1e-09" izz="1e-09" ixy="0" ixz="0" iyz="0"/>
      </inertial>
   </link>
   <joint type="revolute" name="pinky_abd_virt">
      <parent link="palm"/>
      <child link="pinky_abd_virt_jointbody"/>
      <origin xyz="-0.03931395 0.0815 0.0" rpy="-1.5707963267948966 1.5707963267948966 0.0"/>
      <axis xyz="1.0 0.0 0.0"/>
      <limit lower="-0.264" upper="0.264" effort="100" velocity="100"/>
   </joint>
   <joint type="fixed" name="pinky_abd_virt_offset">
      <parent link="pinky_abd_virt_jointbody"/>
      <child link="pinky_um_virt"/>
      <origin xyz="-0.0 -0.0 -0.0" rpy="0.0 0.0 0.0"/>
   </joint>
   <link name="pinky_um">
      <inertial>
         <origin xyz="0.0003137018308382922 -4.3327904489992575e-05 -0.003588735077300156" rpy="3.113495656532974 -1.2922565745690526 -3.099483256875682"/>
         <mass value="0.001706479287008203"/>
         <inertia ixx="4.090623492327608e-08" iyy="3.326893495119032e-08" izz="2.9518955384678924e-08" ixy="0" ixz="0" iyz="0"/>
      </inertial>
      <visual name="pinky_um">
         <origin xyz="0.0003137018308382922 -4.3327904489992575e-05 -0.003588735077300156" rpy="3.1134956565329746 -1.2922565745690526 -3.0994832568756823"/>
         <geometry>
            <mesh filename="package://viz/models/URDF_Simulation/converted_pinky_um.stl"/>
         </geometry>
         <material name="white"/>
      </visual>
   </link>
   <link name="pinky_abd_jointbody">
      <inertial>
         <origin xyz="0.0 0.0 0.0" rpy="0.0 0.0 0.0"/>
         <mass value="0.001"/>
         <inertia ixx="1e-09" iyy="1e-09" izz="1e-09" ixy="0" ixz="0" iyz="0"/>
      </inertial>
   </link>
   <joint type="revolute" name="pinky_abd">
      <parent link="pinky_um_virt"/>
      <child link="pinky_abd_jointbody"/>
      <origin xyz="0.0 0.0 0.018" rpy="0.0 0.0 0.0"/>
      <axis xyz="1.0 0.0 0.0"/>
      <limit lower="-0.264" upper="0.264" effort="100" velocity="100"/>
   </joint>
   <joint type="fixed" name="pinky_abd_offset">
      <parent link="pinky_abd_jointbody"/>
      <child link="pinky_um"/>
      <origin xyz="-0.0 -0.0 -0.0" rpy="0.0 0.0 0.0"/>
   </joint>
   <link name="pinky_pp_virt">
      <inertial>
         <origin xyz="0.0 0.0 0.0" rpy="0.0 0.0 0.0"/>
         <mass value="0.001"/>
         <inertia ixx="4e-10" iyy="4e-10" izz="3e-10" ixy="0" ixz="0" iyz="0"/>
      </inertial>
   </link>
   <link name="root2pinky_pp_virt_jointbody">
      <inertial>
         <origin xyz="0.0 0.0 0.0" rpy="0.0 0.0 0.0"/>
         <mass value="0.001"/>
         <inertia ixx="1e-09" iyy="1e-09" izz="1e-09" ixy="0" ixz="0" iyz="0"/>
      </inertial>
   </link>
   <joint type="revolute" name="root2pinky_pp_virt">
      <parent link="pinky_um"/>
      <child link="root2pinky_pp_virt_jointbody"/>
      <origin xyz="0.00270000102 5.9952065978308155e-19 -0.00743303472" rpy="0.0 0.0 -1.5707963267948963"/>
      <axis xyz="1.0 0.0 0.0"/>
      <limit lower="-0.157" upper="0.829" effort="100" velocity="100"/>
   </joint>
   <joint type="fixed" name="root2pinky_pp_virt_offset">
      <parent link="root2pinky_pp_virt_jointbody"/>
      <child link="pinky_pp_virt"/>
      <origin xyz="-0.0 -0.00270000102 -0.0" rpy="0.0 0.0 0.0"/>
   </joint>
   <link name="pinky_pp">
      <inertial>
         <origin xyz="-2.109461568381571e-05 0.000996163274490867 0.011153640747459392" rpy="-0.0005633739671052629 0.04664075180888805 1.5728100242694358"/>
         <mass value="0.006411007113106174"/>
         <inertia ixx="8.839796343393693e-07" iyy="8.605669091164771e-07" izz="1.4433356510402823e-07" ixy="0" ixz="0" iyz="0"/>
      </inertial>
      <visual name="pinky_pp">
         <origin xyz="-2.109461568381571e-05 0.000996163274490867 0.011153640747459392" rpy="-0.0005633739671052629 0.04664075180888805 1.5728100242694358"/>
         <geometry>
            <mesh filename="package://viz/models/URDF_Simulation/converted_pinky_pp.stl"/>
         </geometry>
         <material name="white"/>
      </visual>
   </link>
   <link name="root2pinky_pp_jointbody">
      <inertial>
         <origin xyz="0.0 0.0 0.0" rpy="0.0 0.0 0.0"/>
         <mass value="0.001"/>
         <inertia ixx="1e-09" iyy="1e-09" izz="1e-09" ixy="0" ixz="0" iyz="0"/>
      </inertial>
   </link>
   <joint type="revolute" name="root2pinky_pp">
      <parent link="pinky_pp_virt"/>
      <child link="root2pinky_pp_jointbody"/>
      <origin xyz="0.0 0.00250000102 0.018" rpy="0.0 0.0 0.0"/>
      <axis xyz="1.0 0.0 0.0"/>
      <limit lower="-0.157" upper="0.829" effort="100" velocity="100"/>
   </joint>
   <joint type="fixed" name="root2pinky_pp_offset">
      <parent link="root2pinky_pp_jointbody"/>
      <child link="pinky_pp"/>
      <origin xyz="-0.0 -0.00250000102 -0.0" rpy="0.0 0.0 0.0"/>
   </joint>
   <link name="pinky_pp_sens">
      <inertial>
         <origin xyz="0.0 -0.004 0.015" rpy="0.0 0.0 0.0"/>
         <mass value="0.0"/>
         <inertia ixx="0.0" iyy="0.0" izz="0.0" ixy="0" ixz="0" iyz="0"/>
      </inertial>
   </link>
   <link name="pinky_pp2pinky_pp_sens_fixed_jointbody">
      <inertial>
         <origin xyz="0.0 0.0 0.0" rpy="0.0 0.0 0.0"/>
         <mass value="0.001"/>
         <inertia ixx="1e-09" iyy="1e-09" izz="1e-09" ixy="0" ixz="0" iyz="0"/>
      </inertial>
   </link>
   <joint type="fixed" name="pinky_pp2pinky_pp_sens_fixed">
      <parent link="pinky_pp"/>
      <child link="pinky_pp2pinky_pp_sens_fixed_jointbody"/>
      <origin xyz="0.0 -0.004 0.015" rpy="0.0 0.0 0.0"/>
   </joint>
   <joint type="fixed" name="pinky_pp2pinky_pp_sens_fixed_offset">
      <parent link="pinky_pp2pinky_pp_sens_fixed_jointbody"/>
      <child link="pinky_pp_sens"/>
      <origin xyz="-0.0 -0.0 -0.0" rpy="0.0 0.0 0.0"/>
   </joint>
   <link name="pinky_mp_virt">
      <inertial>
         <origin xyz="0.0 0.0 0.0" rpy="0.0 0.0 0.0"/>
         <mass value="0.001"/>
         <inertia ixx="4e-10" iyy="4e-10" izz="3e-10" ixy="0" ixz="0" iyz="0"/>
      </inertial>
   </link>
   <link name="pinky_pp2mp_virt_jointbody">
      <inertial>
         <origin xyz="0.0 0.0 0.0" rpy="0.0 0.0 0.0"/>
         <mass value="0.001"/>
         <inertia ixx="1e-09" iyy="1e-09" izz="1e-09" ixy="0" ixz="0" iyz="0"/>
      </inertial>
   </link>
   <joint type="revolute" name="pinky_pp2mp_virt">
      <parent link="pinky_pp"/>
      <child link="pinky_pp2mp_virt_jointbody"/>
      <origin xyz="0.0 0.00370000102 0.02701851213434598" rpy="0.0 0.0 0.0"/>
      <axis xyz="1.0 0.0 0.0"/>
      <limit lower="-0.131" upper="0.96" effort="100" velocity="100"/>
   </joint>
   <joint type="fixed" name="pinky_pp2mp_virt_offset">
      <parent link="pinky_pp2mp_virt_jointbody"/>
      <child link="pinky_mp_virt"/>
      <origin xyz="-0.0 -0.00370000102 -0.0" rpy="0.0 0.0 0.0"/>
   </joint>
   <link name="pinky_mp">
      <inertial>
         <origin xyz="-5.650322932876373e-05 0.0022775589837975138 0.009212500242364308" rpy="0.004881996418440782 0.005874182493044833 1.5691948119058772"/>
         <mass value="0.0035266787657145257"/>
         <inertia ixx="2.591198468813237e-07" iyy="2.327720232400065e-07" izz="6.529283109208708e-08" ixy="0" ixz="0" iyz="0"/>
      </inertial>
      <visual name="pinky_mp">
         <origin xyz="-5.650322932876373e-05 0.0022775589837975138 0.009212500242364308" rpy="0.004881996418440782 0.005874182493044833 1.569194811905877"/>
         <geometry>
            <mesh filename="package://viz/models/URDF_Simulation/converted_pinky_mp.stl"/>
         </geometry>
         <material name="white"/>
      </visual>
   </link>
   <link name="pinky_pp2mp_jointbody">
      <inertial>
         <origin xyz="0.0 0.0 0.0" rpy="0.0 0.0 0.0"/>
         <mass value="0.001"/>
         <inertia ixx="1e-09" iyy="1e-09" izz="1e-09" ixy="0" ixz="0" iyz="0"/>
      </inertial>
   </link>
   <joint type="revolute" name="pinky_pp2mp">
      <parent link="pinky_mp_virt"/>
      <child link="pinky_pp2mp_jointbody"/>
      <origin xyz="0.0 0.00350000102 0.011999999999999999" rpy="0.0 0.0 0.0"/>
      <axis xyz="1.0 0.0 0.0"/>
      <limit lower="-0.131" upper="0.96" effort="100" velocity="100"/>
   </joint>
   <joint type="fixed" name="pinky_pp2mp_offset">
      <parent link="pinky_pp2mp_jointbody"/>
      <child link="pinky_mp"/>
      <origin xyz="-0.0 -0.00350000102 -0.0" rpy="0.0 0.0 0.0"/>
   </joint>
   <link name="pinky_dp_virt">
      <inertial>
         <origin xyz="0.0 0.0 0.0" rpy="0.0 0.0 0.0"/>
         <mass value="0.001"/>
         <inertia ixx="4e-10" iyy="4e-10" izz="3e-10" ixy="0" ixz="0" iyz="0"/>
      </inertial>
   </link>
   <link name="pinky_mp2dp_virt_jointbody">
      <inertial>
         <origin xyz="0.0 0.0 0.0" rpy="0.0 0.0 0.0"/>
         <mass value="0.001"/>
         <inertia ixx="1e-09" iyy="1e-09" izz="1e-09" ixy="0" ixz="0" iyz="0"/>
      </inertial>
   </link>
   <joint type="revolute" name="pinky_mp2dp_virt">
      <parent link="pinky_mp"/>
      <child link="pinky_mp2dp_virt_jointbody"/>
      <origin xyz="0.0 0.00370000102 0.0195" rpy="0.0 0.0 0.0"/>
      <axis xyz="1.0 0.0 0.0"/>
      <limit lower="-0.093" upper="0.682" effort="100" velocity="100"/>
   </joint>
   <joint type="fixed" name="pinky_mp2dp_virt_offset">
      <parent link="pinky_mp2dp_virt_jointbody"/>
      <child link="pinky_dp_virt"/>
      <origin xyz="-0.0 -0.00370000102 -0.0" rpy="0.0 0.0 0.0"/>
   </joint>
   <link name="pinky_dp">
      <inertial>
         <origin xyz="-7.350958926732876e-06 0.0032238257911780463 0.007640724715587549" rpy="0.0038160751754089395 0.053495156395318766 1.57056799955947"/>
         <mass value="0.002076623300267396"/>
         <inertia ixx="1.0632503961582051e-07" iyy="9.094510215249103e-08" izz="2.870836456430631e-08" ixy="0" ixz="0" iyz="0"/>
      </inertial>
      <visual name="pinky_dp">
         <origin xyz="-7.350958926732876e-06 0.0032238257911780463 0.007640724715587549" rpy="0.0038160751754088285 0.053495156395318766 1.57056799955947"/>
         <geometry>
            <mesh filename="package://viz/models/URDF_Simulation/converted_pinky_dp.stl"/>
         </geometry>
         <material name="white"/>
      </visual>
   </link>
   <link name="pinky_mp2dp_jointbody">
      <inertial>
         <origin xyz="0.0 0.0 0.0" rpy="0.0 0.0 0.0"/>
         <mass value="0.001"/>
         <inertia ixx="1e-09" iyy="1e-09" izz="1e-09" ixy="0" ixz="0" iyz="0"/>
      </inertial>
   </link>
   <joint type="revolute" name="pinky_mp2dp">
      <parent link="pinky_dp_virt"/>
      <child link="pinky_mp2dp_jointbody"/>
      <origin xyz="0.0 0.00350000102 0.008999999999999998" rpy="0.0 0.0 0.0"/>
      <axis xyz="1.0 0.0 0.0"/>
      <limit lower="-0.093" upper="0.682" effort="100" velocity="100"/>
   </joint>
   <joint type="fixed" name="pinky_mp2dp_offset">
      <parent link="pinky_mp2dp_jointbody"/>
      <child link="pinky_dp"/>
      <origin xyz="-0.0 -0.00350000102 -0.0" rpy="0.0 0.0 0.0"/>
   </joint>
   <link name="pinky_fingertip">
      <inertial>
         <origin xyz="0.0 0.0 0.01" rpy="0.0 0.0 0.0"/>
         <mass value="0.0"/>
         <inertia ixx="0.0" iyy="0.0" izz="0.0" ixy="0" ixz="0" iyz="0"/>
      </inertial>
   </link>
   <link name="pinky_dp2pinky_fingertip_fixed_jointbody">
      <inertial>
         <origin xyz="0.0 0.0 0.0" rpy="0.0 0.0 0.0"/>
         <mass value="0.001"/>
         <inertia ixx="1e-09" iyy="1e-09" izz="1e-09" ixy="0" ixz="0" iyz="0"/>
      </inertial>
   </link>
   <joint type="fixed" name="pinky_dp2pinky_fingertip_fixed">
      <parent link="pinky_dp"/>
      <child link="pinky_dp2pinky_fingertip_fixed_jointbody"/>
      <origin xyz="0.0 0.0 0.01" rpy="0.0 0.0 0.0"/>
   </joint>
   <joint type="fixed" name="pinky_dp2pinky_fingertip_fixed_offset">
      <parent link="pinky_dp2pinky_fingertip_fixed_jointbody"/>
      <child link="pinky_fingertip"/>
      <origin xyz="-0.0 -0.0 -0.0" rpy="0.0 0.0 0.0"/>
   </joint>
   <material name="white">
      <color rgba="1 1 1 1"/>
   </material>
</robot>
